[2022-10-07 02:27:22,076] {taskinstance.py:1025} INFO - Dependencies not met for <TaskInstance: recruitment-airflow.MongoDBToKafka scheduled__2022-10-06T00:00:00+00:00 [None]>, dependency 'Trigger Rule' FAILED: Task's trigger rule 'all_success' requires all upstream tasks to have succeeded, but found 1 non-success(es). upstream_tasks_state={'total': 1, 'successes': 0, 'skipped': 0, 'failed': 0, 'upstream_failed': 0, 'done': 0}, upstream_task_ids={'crawling'}
[2022-10-07 02:27:22,078] {local_task_job.py:99} INFO - Task is not able to be run
[2022-10-07 02:32:54,162] {taskinstance.py:1035} INFO - Dependencies all met for <TaskInstance: recruitment-airflow.MongoDBToKafka scheduled__2022-10-06T00:00:00+00:00 [queued]>
[2022-10-07 02:32:54,191] {taskinstance.py:1035} INFO - Dependencies all met for <TaskInstance: recruitment-airflow.MongoDBToKafka scheduled__2022-10-06T00:00:00+00:00 [queued]>
[2022-10-07 02:32:54,192] {taskinstance.py:1241} INFO - 
--------------------------------------------------------------------------------
[2022-10-07 02:32:54,194] {taskinstance.py:1242} INFO - Starting attempt 1 of 1
[2022-10-07 02:32:54,194] {taskinstance.py:1243} INFO - 
--------------------------------------------------------------------------------
[2022-10-07 02:32:54,270] {taskinstance.py:1262} INFO - Executing <Task(BashOperator): MongoDBToKafka> on 2022-10-06 00:00:00+00:00
[2022-10-07 02:32:54,273] {standard_task_runner.py:52} INFO - Started process 641 to run task
[2022-10-07 02:32:54,275] {standard_task_runner.py:76} INFO - Running: ['airflow', 'tasks', 'run', 'recruitment-airflow', 'MongoDBToKafka', 'scheduled__2022-10-06T00:00:00+00:00', '--job-id', '48', '--raw', '--subdir', 'DAGS_FOLDER/recruitment_pipeline.py', '--cfg-path', '/tmp/tmpdsz4ggmt', '--error-file', '/tmp/tmp42fd3xog']
[2022-10-07 02:32:54,277] {standard_task_runner.py:77} INFO - Job 48: Subtask MongoDBToKafka
[2022-10-07 02:32:54,364] {logging_mixin.py:109} INFO - Running <TaskInstance: recruitment-airflow.MongoDBToKafka scheduled__2022-10-06T00:00:00+00:00 [running]> on host pipeline
[2022-10-07 02:32:54,413] {logging_mixin.py:109} WARNING - /usr/local/lib/python3.8/site-packages/airflow/models/xcom.py:323 SAWarning: TypeDecorator UtcDateTime(timezone=True) will not produce a cache key because the ``cache_ok`` attribute is not set to True.  This can have significant performance implications including some performance degradations in comparison to prior SQLAlchemy versions.  Set this attribute to True if this type object's state is safe to use in a cache key, or False to disable this warning. (Background on this error at: https://sqlalche.me/e/14/cprf)
[2022-10-07 02:32:54,434] {logging_mixin.py:109} WARNING - /usr/local/lib/python3.8/site-packages/airflow/models/renderedtifields.py:126 SAWarning: TypeDecorator UtcDateTime(timezone=True) will not produce a cache key because the ``cache_ok`` attribute is not set to True.  This can have significant performance implications including some performance degradations in comparison to prior SQLAlchemy versions.  Set this attribute to True if this type object's state is safe to use in a cache key, or False to disable this warning. (Background on this error at: https://sqlalche.me/e/14/cprf)
[2022-10-07 02:32:54,472] {logging_mixin.py:109} WARNING - /usr/local/lib/python3.8/site-packages/airflow/models/renderedtifields.py:162 SAWarning: Coercing Subquery object into a select() for use in IN(); please pass a select() construct explicitly
[2022-10-07 02:32:54,477] {logging_mixin.py:109} WARNING - /usr/local/lib/python3.8/site-packages/airflow/models/renderedtifields.py:159 SAWarning: TypeDecorator UtcDateTime(timezone=True) will not produce a cache key because the ``cache_ok`` attribute is not set to True.  This can have significant performance implications including some performance degradations in comparison to prior SQLAlchemy versions.  Set this attribute to True if this type object's state is safe to use in a cache key, or False to disable this warning. (Background on this error at: https://sqlalche.me/e/14/cprf)
[2022-10-07 02:32:54,494] {taskinstance.py:1427} INFO - Exporting the following env vars:
AIRFLOW_CTX_DAG_OWNER=airflow
AIRFLOW_CTX_DAG_ID=recruitment-airflow
AIRFLOW_CTX_TASK_ID=MongoDBToKafka
AIRFLOW_CTX_EXECUTION_DATE=2022-10-06T00:00:00+00:00
AIRFLOW_CTX_DAG_RUN_ID=scheduled__2022-10-06T00:00:00+00:00
[2022-10-07 02:32:54,497] {subprocess.py:62} INFO - Tmp dir root location: 
 /tmp
[2022-10-07 02:32:54,498] {subprocess.py:74} INFO - Running command: ['bash', '-c', 'python /opt/pipeline/script/MongoDBToKafka.py']
[2022-10-07 02:32:54,504] {subprocess.py:85} INFO - Output:
[2022-10-07 02:33:08,186] {subprocess.py:89} INFO - 1번 째 연결 실패
[2022-10-07 02:33:08,187] {subprocess.py:89} INFO - 2번 째 연결 실패
[2022-10-07 02:33:08,188] {subprocess.py:89} INFO - 3번 째 연결 실패
[2022-10-07 02:33:08,189] {subprocess.py:89} INFO - 4번 째 연결 실패
[2022-10-07 02:33:08,191] {subprocess.py:89} INFO - 5번 째 연결 실패
[2022-10-07 02:33:08,191] {subprocess.py:89} INFO - Kafka를 연결할 수 없습니다
[2022-10-07 02:33:08,193] {subprocess.py:89} INFO - Traceback (most recent call last):
[2022-10-07 02:33:08,194] {subprocess.py:89} INFO -   File "/opt/pipeline/script/MongoDBToKafka.py", line 40, in <module>
[2022-10-07 02:33:08,194] {subprocess.py:89} INFO -     producer.send(topicName, json.dumps(document).encode("utf-8"))
[2022-10-07 02:33:08,195] {subprocess.py:89} INFO - NameError: name 'producer' is not defined
[2022-10-07 02:33:08,725] {subprocess.py:93} INFO - Command exited with return code 1
[2022-10-07 02:33:08,738] {taskinstance.py:1703} ERROR - Task failed with exception
Traceback (most recent call last):
  File "/usr/local/lib/python3.8/site-packages/airflow/models/taskinstance.py", line 1332, in _run_raw_task
    self._execute_task_with_callbacks(context)
  File "/usr/local/lib/python3.8/site-packages/airflow/models/taskinstance.py", line 1458, in _execute_task_with_callbacks
    result = self._execute_task(context, self.task)
  File "/usr/local/lib/python3.8/site-packages/airflow/models/taskinstance.py", line 1514, in _execute_task
    result = execute_callable(context=context)
  File "/usr/local/lib/python3.8/site-packages/airflow/operators/bash.py", line 187, in execute
    raise AirflowException(
airflow.exceptions.AirflowException: Bash command failed. The command returned a non-zero exit code 1.
[2022-10-07 02:33:08,743] {taskinstance.py:1270} INFO - Marking task as FAILED. dag_id=recruitment-airflow, task_id=MongoDBToKafka, execution_date=20221006T000000, start_date=20221007T023254, end_date=20221007T023308
[2022-10-07 02:33:08,821] {standard_task_runner.py:88} ERROR - Failed to execute job 48 for task MongoDBToKafka
Traceback (most recent call last):
  File "/usr/local/lib/python3.8/site-packages/airflow/task/task_runner/standard_task_runner.py", line 85, in _start_by_fork
    args.func(args, dag=self.dag)
  File "/usr/local/lib/python3.8/site-packages/airflow/cli/cli_parser.py", line 48, in command
    return func(*args, **kwargs)
  File "/usr/local/lib/python3.8/site-packages/airflow/utils/cli.py", line 92, in wrapper
    return f(*args, **kwargs)
  File "/usr/local/lib/python3.8/site-packages/airflow/cli/commands/task_command.py", line 292, in task_run
    _run_task_by_selected_method(args, dag, ti)
  File "/usr/local/lib/python3.8/site-packages/airflow/cli/commands/task_command.py", line 107, in _run_task_by_selected_method
    _run_raw_task(args, ti)
  File "/usr/local/lib/python3.8/site-packages/airflow/cli/commands/task_command.py", line 180, in _run_raw_task
    ti._run_raw_task(
  File "/usr/local/lib/python3.8/site-packages/airflow/utils/session.py", line 70, in wrapper
    return func(*args, session=session, **kwargs)
  File "/usr/local/lib/python3.8/site-packages/airflow/models/taskinstance.py", line 1332, in _run_raw_task
    self._execute_task_with_callbacks(context)
  File "/usr/local/lib/python3.8/site-packages/airflow/models/taskinstance.py", line 1458, in _execute_task_with_callbacks
    result = self._execute_task(context, self.task)
  File "/usr/local/lib/python3.8/site-packages/airflow/models/taskinstance.py", line 1514, in _execute_task
    result = execute_callable(context=context)
  File "/usr/local/lib/python3.8/site-packages/airflow/operators/bash.py", line 187, in execute
    raise AirflowException(
airflow.exceptions.AirflowException: Bash command failed. The command returned a non-zero exit code 1.
[2022-10-07 02:33:08,865] {local_task_job.py:154} INFO - Task exited with return code 1
[2022-10-07 02:33:08,957] {local_task_job.py:264} INFO - 0 downstream tasks scheduled from follow-on schedule check
[2022-10-07 02:33:08,959] {logging_mixin.py:109} WARNING - /usr/local/lib/python3.8/site-packages/airflow/models/dag.py:1069 SADeprecationWarning: Query.value() is deprecated and will be removed in a future release.  Please use Query.with_entities() in combination with Query.scalar() (deprecated since: 1.4)
[2022-10-07 02:33:08,960] {logging_mixin.py:109} WARNING - /usr/local/lib/python3.8/site-packages/airflow/models/dag.py:1069 SADeprecationWarning: Query.values() is deprecated and will be removed in a future release.  Please use Query.with_entities() (deprecated since: 1.4)
