[2022-10-08 15:15:20,317] {taskinstance.py:1035} INFO - Dependencies all met for <TaskInstance: recruitment-airflow.KafkaConnectTest scheduled__2022-10-07T00:00:00+00:00 [queued]>
[2022-10-08 15:15:20,343] {taskinstance.py:1035} INFO - Dependencies all met for <TaskInstance: recruitment-airflow.KafkaConnectTest scheduled__2022-10-07T00:00:00+00:00 [queued]>
[2022-10-08 15:15:20,343] {taskinstance.py:1241} INFO - 
--------------------------------------------------------------------------------
[2022-10-08 15:15:20,344] {taskinstance.py:1242} INFO - Starting attempt 1 of 1
[2022-10-08 15:15:20,345] {taskinstance.py:1243} INFO - 
--------------------------------------------------------------------------------
[2022-10-08 15:15:20,410] {taskinstance.py:1262} INFO - Executing <Task(BashOperator): KafkaConnectTest> on 2022-10-07 00:00:00+00:00
[2022-10-08 15:15:20,412] {standard_task_runner.py:52} INFO - Started process 33 to run task
[2022-10-08 15:15:20,415] {standard_task_runner.py:76} INFO - Running: ['airflow', 'tasks', 'run', 'recruitment-airflow', 'KafkaConnectTest', 'scheduled__2022-10-07T00:00:00+00:00', '--job-id', '76', '--raw', '--subdir', 'DAGS_FOLDER/recruitment_pipeline.py', '--cfg-path', '/tmp/tmph4xu2ul4', '--error-file', '/tmp/tmpili508v5']
[2022-10-08 15:15:20,417] {standard_task_runner.py:77} INFO - Job 76: Subtask KafkaConnectTest
[2022-10-08 15:15:20,504] {logging_mixin.py:109} INFO - Running <TaskInstance: recruitment-airflow.KafkaConnectTest scheduled__2022-10-07T00:00:00+00:00 [running]> on host pipeline
[2022-10-08 15:15:20,557] {logging_mixin.py:109} WARNING - /usr/local/lib/python3.8/site-packages/airflow/models/xcom.py:323 SAWarning: TypeDecorator UtcDateTime(timezone=True) will not produce a cache key because the ``cache_ok`` attribute is not set to True.  This can have significant performance implications including some performance degradations in comparison to prior SQLAlchemy versions.  Set this attribute to True if this type object's state is safe to use in a cache key, or False to disable this warning. (Background on this error at: https://sqlalche.me/e/14/cprf)
[2022-10-08 15:15:20,581] {logging_mixin.py:109} WARNING - /usr/local/lib/python3.8/site-packages/airflow/models/renderedtifields.py:126 SAWarning: TypeDecorator UtcDateTime(timezone=True) will not produce a cache key because the ``cache_ok`` attribute is not set to True.  This can have significant performance implications including some performance degradations in comparison to prior SQLAlchemy versions.  Set this attribute to True if this type object's state is safe to use in a cache key, or False to disable this warning. (Background on this error at: https://sqlalche.me/e/14/cprf)
[2022-10-08 15:15:20,625] {logging_mixin.py:109} WARNING - /usr/local/lib/python3.8/site-packages/airflow/models/renderedtifields.py:162 SAWarning: Coercing Subquery object into a select() for use in IN(); please pass a select() construct explicitly
[2022-10-08 15:15:20,629] {logging_mixin.py:109} WARNING - /usr/local/lib/python3.8/site-packages/airflow/models/renderedtifields.py:159 SAWarning: TypeDecorator UtcDateTime(timezone=True) will not produce a cache key because the ``cache_ok`` attribute is not set to True.  This can have significant performance implications including some performance degradations in comparison to prior SQLAlchemy versions.  Set this attribute to True if this type object's state is safe to use in a cache key, or False to disable this warning. (Background on this error at: https://sqlalche.me/e/14/cprf)
[2022-10-08 15:15:20,648] {taskinstance.py:1427} INFO - Exporting the following env vars:
AIRFLOW_CTX_DAG_OWNER=airflow
AIRFLOW_CTX_DAG_ID=recruitment-airflow
AIRFLOW_CTX_TASK_ID=KafkaConnectTest
AIRFLOW_CTX_EXECUTION_DATE=2022-10-07T00:00:00+00:00
AIRFLOW_CTX_DAG_RUN_ID=scheduled__2022-10-07T00:00:00+00:00
[2022-10-08 15:15:20,650] {subprocess.py:62} INFO - Tmp dir root location: 
 /tmp
[2022-10-08 15:15:20,651] {subprocess.py:74} INFO - Running command: ['bash', '-c', 'python /opt/pipeline/script/KafkaConnectTest.py']
[2022-10-08 15:15:20,656] {subprocess.py:85} INFO - Output:
[2022-10-08 15:15:22,581] {process_utils.py:100} INFO - Sending Signals.SIGTERM to GPID 33
[2022-10-08 15:15:22,586] {taskinstance.py:1411} ERROR - Received SIGTERM. Terminating subprocesses.
[2022-10-08 15:15:22,589] {subprocess.py:99} INFO - Sending SIGTERM signal to process group
[2022-10-08 15:15:22,625] {taskinstance.py:1703} ERROR - Task failed with exception
Traceback (most recent call last):
  File "/usr/local/lib/python3.8/site-packages/airflow/models/taskinstance.py", line 1332, in _run_raw_task
    self._execute_task_with_callbacks(context)
  File "/usr/local/lib/python3.8/site-packages/airflow/models/taskinstance.py", line 1458, in _execute_task_with_callbacks
    result = self._execute_task(context, self.task)
  File "/usr/local/lib/python3.8/site-packages/airflow/models/taskinstance.py", line 1514, in _execute_task
    result = execute_callable(context=context)
  File "/usr/local/lib/python3.8/site-packages/airflow/operators/bash.py", line 178, in execute
    result = self.subprocess_hook.run_command(
  File "/usr/local/lib/python3.8/site-packages/airflow/hooks/subprocess.py", line 87, in run_command
    for raw_line in iter(self.sub_process.stdout.readline, b''):
  File "/usr/local/lib/python3.8/site-packages/airflow/models/taskinstance.py", line 1413, in signal_handler
    raise AirflowException("Task received SIGTERM signal")
airflow.exceptions.AirflowException: Task received SIGTERM signal
[2022-10-08 15:15:22,634] {taskinstance.py:1270} INFO - Marking task as FAILED. dag_id=recruitment-airflow, task_id=KafkaConnectTest, execution_date=20221007T000000, start_date=20221008T151520, end_date=20221008T151522
[2022-10-08 15:15:22,718] {standard_task_runner.py:88} ERROR - Failed to execute job 76 for task KafkaConnectTest
Traceback (most recent call last):
  File "/usr/local/lib/python3.8/site-packages/airflow/task/task_runner/standard_task_runner.py", line 85, in _start_by_fork
    args.func(args, dag=self.dag)
  File "/usr/local/lib/python3.8/site-packages/airflow/cli/cli_parser.py", line 48, in command
    return func(*args, **kwargs)
  File "/usr/local/lib/python3.8/site-packages/airflow/utils/cli.py", line 92, in wrapper
    return f(*args, **kwargs)
  File "/usr/local/lib/python3.8/site-packages/airflow/cli/commands/task_command.py", line 292, in task_run
    _run_task_by_selected_method(args, dag, ti)
  File "/usr/local/lib/python3.8/site-packages/airflow/cli/commands/task_command.py", line 107, in _run_task_by_selected_method
    _run_raw_task(args, ti)
  File "/usr/local/lib/python3.8/site-packages/airflow/cli/commands/task_command.py", line 180, in _run_raw_task
    ti._run_raw_task(
  File "/usr/local/lib/python3.8/site-packages/airflow/utils/session.py", line 70, in wrapper
    return func(*args, session=session, **kwargs)
  File "/usr/local/lib/python3.8/site-packages/airflow/models/taskinstance.py", line 1332, in _run_raw_task
    self._execute_task_with_callbacks(context)
  File "/usr/local/lib/python3.8/site-packages/airflow/models/taskinstance.py", line 1458, in _execute_task_with_callbacks
    result = self._execute_task(context, self.task)
  File "/usr/local/lib/python3.8/site-packages/airflow/models/taskinstance.py", line 1514, in _execute_task
    result = execute_callable(context=context)
  File "/usr/local/lib/python3.8/site-packages/airflow/operators/bash.py", line 178, in execute
    result = self.subprocess_hook.run_command(
  File "/usr/local/lib/python3.8/site-packages/airflow/hooks/subprocess.py", line 87, in run_command
    for raw_line in iter(self.sub_process.stdout.readline, b''):
  File "/usr/local/lib/python3.8/site-packages/airflow/models/taskinstance.py", line 1413, in signal_handler
    raise AirflowException("Task received SIGTERM signal")
airflow.exceptions.AirflowException: Task received SIGTERM signal
[2022-10-08 15:15:23,099] {process_utils.py:66} INFO - Process psutil.Process(pid=33, status='terminated', exitcode=1, started='15:15:19') (33) terminated with exit code 1
