[2022-10-07 04:52:22,418] {taskinstance.py:1035} INFO - Dependencies all met for <TaskInstance: recruitment-airflow.S3ToMySQL manual__2022-10-07T04:48:02.280389+00:00 [queued]>
[2022-10-07 04:52:22,451] {taskinstance.py:1035} INFO - Dependencies all met for <TaskInstance: recruitment-airflow.S3ToMySQL manual__2022-10-07T04:48:02.280389+00:00 [queued]>
[2022-10-07 04:52:22,453] {taskinstance.py:1241} INFO - 
--------------------------------------------------------------------------------
[2022-10-07 04:52:22,454] {taskinstance.py:1242} INFO - Starting attempt 1 of 1
[2022-10-07 04:52:22,455] {taskinstance.py:1243} INFO - 
--------------------------------------------------------------------------------
[2022-10-07 04:52:22,517] {taskinstance.py:1262} INFO - Executing <Task(BashOperator): S3ToMySQL> on 2022-10-07 04:48:02.280389+00:00
[2022-10-07 04:52:22,521] {standard_task_runner.py:52} INFO - Started process 237 to run task
[2022-10-07 04:52:22,523] {standard_task_runner.py:76} INFO - Running: ['airflow', 'tasks', 'run', 'recruitment-airflow', 'S3ToMySQL', 'manual__2022-10-07T04:48:02.280389+00:00', '--job-id', '74', '--raw', '--subdir', 'DAGS_FOLDER/recruitment_pipeline.py', '--cfg-path', '/tmp/tmp_78m0r0w', '--error-file', '/tmp/tmpuod8v883']
[2022-10-07 04:52:22,524] {standard_task_runner.py:77} INFO - Job 74: Subtask S3ToMySQL
[2022-10-07 04:52:22,610] {logging_mixin.py:109} INFO - Running <TaskInstance: recruitment-airflow.S3ToMySQL manual__2022-10-07T04:48:02.280389+00:00 [running]> on host pipeline
[2022-10-07 04:52:22,663] {logging_mixin.py:109} WARNING - /usr/local/lib/python3.8/site-packages/airflow/models/xcom.py:323 SAWarning: TypeDecorator UtcDateTime(timezone=True) will not produce a cache key because the ``cache_ok`` attribute is not set to True.  This can have significant performance implications including some performance degradations in comparison to prior SQLAlchemy versions.  Set this attribute to True if this type object's state is safe to use in a cache key, or False to disable this warning. (Background on this error at: https://sqlalche.me/e/14/cprf)
[2022-10-07 04:52:22,685] {logging_mixin.py:109} WARNING - /usr/local/lib/python3.8/site-packages/airflow/models/renderedtifields.py:126 SAWarning: TypeDecorator UtcDateTime(timezone=True) will not produce a cache key because the ``cache_ok`` attribute is not set to True.  This can have significant performance implications including some performance degradations in comparison to prior SQLAlchemy versions.  Set this attribute to True if this type object's state is safe to use in a cache key, or False to disable this warning. (Background on this error at: https://sqlalche.me/e/14/cprf)
[2022-10-07 04:52:22,725] {logging_mixin.py:109} WARNING - /usr/local/lib/python3.8/site-packages/airflow/models/renderedtifields.py:162 SAWarning: Coercing Subquery object into a select() for use in IN(); please pass a select() construct explicitly
[2022-10-07 04:52:22,729] {logging_mixin.py:109} WARNING - /usr/local/lib/python3.8/site-packages/airflow/models/renderedtifields.py:159 SAWarning: TypeDecorator UtcDateTime(timezone=True) will not produce a cache key because the ``cache_ok`` attribute is not set to True.  This can have significant performance implications including some performance degradations in comparison to prior SQLAlchemy versions.  Set this attribute to True if this type object's state is safe to use in a cache key, or False to disable this warning. (Background on this error at: https://sqlalche.me/e/14/cprf)
[2022-10-07 04:52:22,747] {taskinstance.py:1427} INFO - Exporting the following env vars:
AIRFLOW_CTX_DAG_OWNER=airflow
AIRFLOW_CTX_DAG_ID=recruitment-airflow
AIRFLOW_CTX_TASK_ID=S3ToMySQL
AIRFLOW_CTX_EXECUTION_DATE=2022-10-07T04:48:02.280389+00:00
AIRFLOW_CTX_DAG_RUN_ID=manual__2022-10-07T04:48:02.280389+00:00
[2022-10-07 04:52:22,748] {subprocess.py:62} INFO - Tmp dir root location: 
 /tmp
[2022-10-07 04:52:22,750] {subprocess.py:74} INFO - Running command: ['bash', '-c', 'python /opt/pipeline/script/S3ToMySQL.py']
[2022-10-07 04:52:22,754] {subprocess.py:85} INFO - Output:
[2022-10-07 04:52:23,156] {subprocess.py:89} INFO - Traceback (most recent call last):
[2022-10-07 04:52:23,158] {subprocess.py:89} INFO -   File "/opt/pipeline/script/S3ToMySQL.py", line 24, in <module>
[2022-10-07 04:52:23,159] {subprocess.py:89} INFO -     dataBase = mysql.connector.connect(
[2022-10-07 04:52:23,160] {subprocess.py:89} INFO -   File "/usr/local/lib/python3.8/site-packages/mysql/connector/pooling.py", line 287, in connect
[2022-10-07 04:52:23,161] {subprocess.py:89} INFO -     return MySQLConnection(*args, **kwargs)
[2022-10-07 04:52:23,162] {subprocess.py:89} INFO -   File "/usr/local/lib/python3.8/site-packages/mysql/connector/connection.py", line 137, in __init__
[2022-10-07 04:52:23,163] {subprocess.py:89} INFO -     self.connect(**kwargs)
[2022-10-07 04:52:23,165] {subprocess.py:89} INFO -   File "/usr/local/lib/python3.8/site-packages/mysql/connector/abstracts.py", line 1095, in connect
[2022-10-07 04:52:23,167] {subprocess.py:89} INFO -     self._open_connection()
[2022-10-07 04:52:23,168] {subprocess.py:89} INFO -   File "/usr/local/lib/python3.8/site-packages/mysql/connector/connection.py", line 535, in _open_connection
[2022-10-07 04:52:23,170] {subprocess.py:89} INFO -     self._do_auth(
[2022-10-07 04:52:23,171] {subprocess.py:89} INFO -   File "/usr/local/lib/python3.8/site-packages/mysql/connector/connection.py", line 279, in _do_auth
[2022-10-07 04:52:23,172] {subprocess.py:89} INFO -     self._auth_switch_request(username, password)
[2022-10-07 04:52:23,173] {subprocess.py:89} INFO -   File "/usr/local/lib/python3.8/site-packages/mysql/connector/connection.py", line 332, in _auth_switch_request
[2022-10-07 04:52:23,174] {subprocess.py:89} INFO -     raise get_exception(packet)
[2022-10-07 04:52:23,176] {subprocess.py:89} INFO - mysql.connector.errors.ProgrammingError: 1049 (42000): Unknown database 'recruitment'
[2022-10-07 04:52:23,261] {subprocess.py:93} INFO - Command exited with return code 1
[2022-10-07 04:52:23,282] {taskinstance.py:1703} ERROR - Task failed with exception
Traceback (most recent call last):
  File "/usr/local/lib/python3.8/site-packages/airflow/models/taskinstance.py", line 1332, in _run_raw_task
    self._execute_task_with_callbacks(context)
  File "/usr/local/lib/python3.8/site-packages/airflow/models/taskinstance.py", line 1458, in _execute_task_with_callbacks
    result = self._execute_task(context, self.task)
  File "/usr/local/lib/python3.8/site-packages/airflow/models/taskinstance.py", line 1514, in _execute_task
    result = execute_callable(context=context)
  File "/usr/local/lib/python3.8/site-packages/airflow/operators/bash.py", line 187, in execute
    raise AirflowException(
airflow.exceptions.AirflowException: Bash command failed. The command returned a non-zero exit code 1.
[2022-10-07 04:52:23,288] {taskinstance.py:1270} INFO - Marking task as FAILED. dag_id=recruitment-airflow, task_id=S3ToMySQL, execution_date=20221007T044802, start_date=20221007T045222, end_date=20221007T045223
[2022-10-07 04:52:23,360] {standard_task_runner.py:88} ERROR - Failed to execute job 74 for task S3ToMySQL
Traceback (most recent call last):
  File "/usr/local/lib/python3.8/site-packages/airflow/task/task_runner/standard_task_runner.py", line 85, in _start_by_fork
    args.func(args, dag=self.dag)
  File "/usr/local/lib/python3.8/site-packages/airflow/cli/cli_parser.py", line 48, in command
    return func(*args, **kwargs)
  File "/usr/local/lib/python3.8/site-packages/airflow/utils/cli.py", line 92, in wrapper
    return f(*args, **kwargs)
  File "/usr/local/lib/python3.8/site-packages/airflow/cli/commands/task_command.py", line 292, in task_run
    _run_task_by_selected_method(args, dag, ti)
  File "/usr/local/lib/python3.8/site-packages/airflow/cli/commands/task_command.py", line 107, in _run_task_by_selected_method
    _run_raw_task(args, ti)
  File "/usr/local/lib/python3.8/site-packages/airflow/cli/commands/task_command.py", line 180, in _run_raw_task
    ti._run_raw_task(
  File "/usr/local/lib/python3.8/site-packages/airflow/utils/session.py", line 70, in wrapper
    return func(*args, session=session, **kwargs)
  File "/usr/local/lib/python3.8/site-packages/airflow/models/taskinstance.py", line 1332, in _run_raw_task
    self._execute_task_with_callbacks(context)
  File "/usr/local/lib/python3.8/site-packages/airflow/models/taskinstance.py", line 1458, in _execute_task_with_callbacks
    result = self._execute_task(context, self.task)
  File "/usr/local/lib/python3.8/site-packages/airflow/models/taskinstance.py", line 1514, in _execute_task
    result = execute_callable(context=context)
  File "/usr/local/lib/python3.8/site-packages/airflow/operators/bash.py", line 187, in execute
    raise AirflowException(
airflow.exceptions.AirflowException: Bash command failed. The command returned a non-zero exit code 1.
[2022-10-07 04:52:23,385] {local_task_job.py:154} INFO - Task exited with return code 1
[2022-10-07 04:52:23,421] {local_task_job.py:264} INFO - 0 downstream tasks scheduled from follow-on schedule check
[2022-10-07 04:52:23,423] {logging_mixin.py:109} WARNING - /usr/local/lib/python3.8/site-packages/airflow/models/dag.py:1069 SADeprecationWarning: Query.value() is deprecated and will be removed in a future release.  Please use Query.with_entities() in combination with Query.scalar() (deprecated since: 1.4)
[2022-10-07 04:52:23,425] {logging_mixin.py:109} WARNING - /usr/local/lib/python3.8/site-packages/airflow/models/dag.py:1069 SADeprecationWarning: Query.values() is deprecated and will be removed in a future release.  Please use Query.with_entities() (deprecated since: 1.4)
